<?xml version="1.0" ?>
<!-- =================================================================================== -->
<!-- |    This document was autogenerated by xacro from cyclairbot_urdf.xacro          | -->
<!-- |    EDITING THIS FILE BY HAND IS NOT RECOMMENDED                                 | -->
<!-- =================================================================================== -->
<robot name="neo_lwrtorso">
  <!-- ros2_control plugin -->
  <gazebo reference="main_box">
    <material>Gazebo/Orange</material>
  </gazebo>
  <!--Front wheel assembly-->
   &quot;realsense_baselink&quot;/
    
  <gazebo reference="fl_leg">
      
    </gazebo>
  <gazebo reference="wheel_fl">
      
    </gazebo>
  <gazebo reference="fr_leg">
      
    </gazebo>
  <gazebo reference="wheel_fr">
      
    </gazebo>
  <gazebo reference="bl_leg">
      
    </gazebo>
  <gazebo reference="wheel_bl">

    </gazebo>
  <gazebo reference="br_leg">
      
    </gazebo>
  <gazebo reference="wheel_br">

    </gazebo>
  <gazebo reference="realsense_baselink">
    </gazebo>
  <gazebo reference="camera_link">
    </gazebo>
  <!-- Rover should be facing X axis -->
  <!--Despite the name, this is actually gray plastic.-->
  <material name="grey_plastic">
    <!-- <unreal_material path="Material'/AirSim/VehicleAdv/SUV/AutomotiveMaterials/Materials/Plastic/MI_Plastic_Matte_Black.MI_Plastic_Matte_Black'"/> -->
    <color rgba="0 1.0 1.0 1.0"/>
  </material>
  <material name="black_plastic">
    <!-- <unreal_material path="Material'/AirSim/VehicleAdv/SUV/AutomotiveMaterials/Materials/Plastic/M_Plastic_Matte.M_Plastic_Matte'"/> -->
    <color rgba="0 1.0 1.0 1.0"/>
  </material>
  <material name="tire_rubber">
    <!-- <unreal_material path="Material'/AirSim/VehicleAdv/SUV/AutomotiveMaterials/Materials/Rubber/M_TireRubber.M_TireRubber'"/> -->
    <color rgba="0 1.0 1.0 1.0"/>
  </material>
  <link name="base_footprint"/>
  <joint name="footprint_mainbox" type="fixed">
    <parent link="base_footprint"/>
    <child link="main_box"/>
    <origin rpy="0 0 0" xyz="0 0 0.3"/>
    <axis rpy="0 0 0" xyz="0 0 1"/>
  </joint>
  <link name="main_box">
    <visual>
      <geometry>
        <box size="1 0.8 0.6"/>
      </geometry>
      <material name="black_plastic"/>
    </visual>
    <collision>
      <geometry>
        <!-- The to-be-commented XML block goes here. -->
        <box size="1 0.8 0.6"/>
      </geometry>
    </collision>
    <inertial>
      <mass value="100"/>
      <inertia ixx="1.0" ixy="0.0" ixz="0.0" iyy="1.0" iyz="0.0" izz="1.0"/>
    </inertial>
  </link>
  <!-- FRONT LEFT LEG -->
  <link name="fl_leg">
    <visual>
      <geometry>
        <box size="0.1 0.1 0.6"/>
      </geometry>
      <material name="black_plastic"/>
    </visual>
    <collision>
      <geometry>
        <box size="0.1 0.1 0.6"/>
      </geometry>
    </collision>
    <inertial>
      <mass value="6"/>
      <inertia ixx="1.0" ixy="0.0" ixz="0.0" iyy="1.0" iyz="0.0" izz="1.0"/>
    </inertial>
  </link>
  <joint name="main_box_to_fl_leg" type="fixed">
    <parent link="main_box"/>
    <child link="fl_leg"/>
    <origin rpy="0 -0.35 0" xyz="0.5 -0.45 -0.5"/>
    <axis rpy="0 0 0" xyz="0 0 1"/>
  </joint>
  <link name="wheel_fl">
    <visual>
      <geometry>
        <cylinder length="0.15" radius="0.2"/>
      </geometry>
      <material name="tire_rubber"/>
    </visual>
    <collision>
      <geometry>
        <cylinder length="0.15" radius="0.2"/>
      </geometry>
    </collision>
    <inertial>
      <mass value="3"/>
      <inertia ixx="1.0" ixy="0.0" ixz="0.0" iyy="1.0" iyz="0.0" izz="1.0"/>
    </inertial>
  </link>
  <joint name="fl_leg_to_wheel_fl" type="continuous">
    <parent link="fl_leg"/>
    <child link="wheel_fl"/>
    <origin rpy="0 1.5707 1.5707" xyz="0.0 -0.13 -0.20"/>
    <axis rpy="0 0 0" xyz="0 0 1"/>
    <!-- <limit lower="0" upper="0" effort="20" velocity="1"/> -->
  </joint>
  <!--============================================================================-->
  <!-- FRONT RIGHT LEG -->
  <link name="fr_leg">
    <visual>
      <geometry>
        <box size="0.1 0.1 0.6"/>
      </geometry>
      <material name="black_plastic"/>
    </visual>
    <collision>
      <geometry>
        <box size="0.1 0.1 0.6"/>
      </geometry>
    </collision>
    <inertial>
      <mass value="6"/>
      <inertia ixx="1.0" ixy="0.0" ixz="0.0" iyy="1.0" iyz="0.0" izz="1.0"/>
    </inertial>
  </link>
  <joint name="main_box_to_fr_leg" type="fixed">
    <parent link="main_box"/>
    <child link="fr_leg"/>
    <origin rpy="0 -0.35 0" xyz="0.5 0.45 -0.5"/>
    <axis rpy="0 0 0" xyz="0 0 1"/>
  </joint>
  <link name="wheel_fr">
    <visual>
      <geometry>
        <cylinder length="0.15" radius="0.2"/>
      </geometry>
      <material name="tire_rubber"/>
    </visual>
    <collision>
      <geometry>
        <cylinder length="0.15" radius="0.2"/>
      </geometry>
    </collision>
    <inertial>
      <mass value="3"/>
      <inertia ixx="1.0" ixy="0.0" ixz="0.0" iyy="1.0" iyz="0.0" izz="1.0"/>
    </inertial>
  </link>
  <joint name="fr_leg_to_wheel_fr" type="continuous">
    <parent link="fr_leg"/>
    <child link="wheel_fr"/>
    <origin rpy="0 1.5707 1.5707" xyz="0.0 0.13 -0.20"/>
    <axis rpy="0 0 0" xyz="0 0 1"/>
    <!-- <limit lower="0" upper="0" effort="20" velocity="1"/> -->
  </joint>
  <!-- BACK STEERING LEFT LEG ===================================================== -->
  <link name="bl_leg">
    <visual>
      <geometry>
        <cylinder length="0.6" radius="0.05"/>
      </geometry>
      <material name="black_plastic"/>
    </visual>
    <collision>
      <geometry>
        <cylinder length="0.6" radius="0.05"/>
      </geometry>
    </collision>
    <inertial>
      <mass value="6"/>
      <inertia ixx="1.0" ixy="0.0" ixz="0.0" iyy="1.0" iyz="0.0" izz="1.0"/>
    </inertial>
  </link>
  <joint name="main_box_to_bl_leg" type="revolute">
    <parent link="main_box"/>
    <child link="bl_leg"/>
    <origin rpy="0 0 0" xyz="-0.5 -0.45 -0.5"/>
    <axis rpy="0 0 0" xyz="0 0 1"/>
    <limit effort="10" lower="-0.5" upper="0.5" velocity="0.5"/>
  </joint>
  <link name="wheel_bl">
    <visual>
      <geometry>
        <cylinder length="0.15" radius="0.2"/>
      </geometry>
      <material name="tire_rubber"/>
    </visual>
    <collision>
      <geometry>
        <cylinder length="0.15" radius="0.2"/>
      </geometry>
    </collision>
    <inertial>
      <mass value="6"/>
      <inertia ixx="1.0" ixy="0.0" ixz="0.0" iyy="1.0" iyz="0.0" izz="1.0"/>
    </inertial>
  </link>
  <joint name="bl_leg_to_wheel_bl" type="continuous">
    <parent link="bl_leg"/>
    <child link="wheel_bl"/>
    <origin rpy="0 1.5707 1.5707" xyz="0.0 -0.13 -0.2"/>
    <axis rpy="0 0 0" xyz="0 0 1"/>
    <limit effort="10000" lower="0" upper="0" velocity="1"/>
  </joint>
  <!-- BACK STEERING RIGHT LEG ====================================================-->
  <link name="br_leg">
    <visual>
      <geometry>
        <cylinder length="0.6" radius="0.05"/>
      </geometry>
      <material name="black_plastic"/>
    </visual>
    <collision>
      <geometry>
        <cylinder length="0.6" radius="0.05"/>
      </geometry>
    </collision>
    <inertial>
      <mass value="6"/>
      <inertia ixx="1.0" ixy="0.0" ixz="0.0" iyy="1.0" iyz="0.0" izz="1.0"/>
    </inertial>
  </link>
  <joint name="main_box_to_br_leg" type="revolute">
    <parent link="main_box"/>
    <child link="br_leg"/>
    <origin rpy="0 0 0" xyz="-0.5 0.45 -0.5"/>
    <axis rpy="0 0 0" xyz="0 0 1"/>
    <limit effort="10" lower="-0.5" upper="0.5" velocity="0.5"/>
  </joint>
  <link name="wheel_br">
    <visual>
      <geometry>
        <cylinder length="0.15" radius="0.2"/>
      </geometry>
      <material name="tire_rubber"/>
    </visual>
    <collision>
      <geometry>
        <cylinder length="0.15" radius="0.2"/>
      </geometry>
    </collision>
    <inertial>
      <mass value="6"/>
      <inertia ixx="1.0" ixy="0.0" ixz="0.0" iyy="1.0" iyz="0.0" izz="1.0"/>
    </inertial>
  </link>
  <joint name="br_leg_to_wheel_br" type="continuous">
    <parent link="br_leg"/>
    <child link="wheel_br"/>
    <origin rpy="0 1.5707 1.5707" xyz="0.0 0.13 -0.2"/>
    <axis rpy="0 0 0" xyz="0 0 1"/>
    <limit effort="10000" lower="0" upper="0" velocity="1"/>
  </joint>
  <material name="aluminum">
    <color rgba="0.5 0.5 0.5 1"/>
  </material>
  <material name="plastic">
    <color rgba="0.1 0.1 0.1 1"/>
  </material>
  <link name="realsense_baselink"/>
  <!-- camera body, with origin at bottom screw mount -->
  <joint name="camera_joint" type="fixed">
    <origin rpy="0 0 0" xyz="0 0 1"/>
    <parent link="realsense_baselink"/>
    <child link="camera_bottom_screw_frame"/>
  </joint>
  <gazebo reference="camera_bottom_screw_frame"/>
  <link name="camera_bottom_screw_frame"/>
  <joint name="camera_link_joint" type="fixed">
    <origin rpy="0 0 0" xyz="0.010600000000000002 0.0175 0.0125"/>
    <parent link="camera_bottom_screw_frame"/>
    <child link="camera_link"/>
  </joint>
  <link name="camera_link">
    <visual>
      <!-- the mesh origin is at front plate in between the two infrared camera axes -->
      <origin rpy="1.5707963267948966 0 1.5707963267948966" xyz="0.0043 -0.0175 0"/>
      <geometry>
        <mesh filename="/home/drone2021/satvikbot_ws/ros2_ws/src/realsense2_description/meshes/d435.dae"/>
      </geometry>
    </visual>
    <collision>
      <origin rpy="0 0 0" xyz="0 -0.0175 0"/>
      <geometry>
        <box size="0.02505 0.09 0.025"/>
      </geometry>
    </collision>
    <inertial>
      <!-- The following are not reliable values, and should not be used for modeling -->
      <mass value="0.072"/>
      <origin xyz="0 0 0"/>
      <inertia ixx="0.003881243" ixy="0.0" ixz="0.0" iyy="0.000498940" iyz="0.0" izz="0.003879257"/>
    </inertial>
  </link>
  <gazebo reference="camera_link"/>
  <joint name="realsense_bot" type="fixed">
    <parent link="main_box"/>
    <child link="realsense_baselink"/>
    <origin rpy="0 0 0" xyz="1 1 1.3"/>
    <axis rpy="0 0 0" xyz="0 0 1"/>
  </joint>
</robot>
