<?xml version="1.0" ?>
<!-- =================================================================================== -->
<!-- |    This document was autogenerated by xacro from cyclairbot_urdf.xacro          | -->
<!-- |    EDITING THIS FILE BY HAND IS NOT RECOMMENDED                                 | -->
<!-- =================================================================================== -->
<robot name="neo_lwrtorso">
  <!-- ros2_control plugin -->
  <gazebo>
    <plugin filename="libgazebo_ros_diff_drive.so" name="diff_drive">
      <!-- wheels -->
      <left_joint>bl_leg_to_wheel_bl</left_joint>
      <right_joint>br_leg_to_wheel_br</right_joint>
      <!-- kinematics -->
      <wheel_separation>1.55</wheel_separation>
      <wheel_diameter>0.4</wheel_diameter>
      <!-- limits -->
      <max_wheel_torque>20</max_wheel_torque>
      <max_wheel_acceleration>1.0</max_wheel_acceleration>
      <!-- output -->
      <publish_odom>true</publish_odom>
      <publish_odom_tf>true</publish_odom_tf>
      <publish_wheel_tf>true</publish_wheel_tf>
      <odometry_frame>odom</odometry_frame>
      <robot_base_frame>main_box</robot_base_frame>
    </plugin>
  </gazebo>
  <gazebo reference="main_box">
    <material>Gazebo/Orange</material>
  </gazebo>
  <!--Front wheel assembly-->
   &quot;realsense_baselink&quot;/
    
  <gazebo reference="fl_leg">
      
    </gazebo>
  <gazebo reference="wheel_fl">
      
    </gazebo>
  <gazebo reference="fr_leg">
      
    </gazebo>
  <gazebo reference="wheel_fr">
      
    </gazebo>
  <gazebo reference="bl_leg">
      
    </gazebo>
  <gazebo reference="wheel_bl">

    </gazebo>
  <gazebo reference="br_leg">
      
    </gazebo>
  <gazebo reference="wheel_br">

    </gazebo>
  <gazebo reference="realsense_baselink">
    </gazebo>
  <gazebo reference="camera_link">
    </gazebo>
  <!-- Rover should be facing X axis -->
  <!--Despite the name, this is actually gray plastic.-->
  <material name="grey_plastic">
    <!-- <unreal_material path="Material'/AirSim/VehicleAdv/SUV/AutomotiveMaterials/Materials/Plastic/MI_Plastic_Matte_Black.MI_Plastic_Matte_Black'"/> -->
    <color rgba="0 1.0 1.0 1.0"/>
  </material>
  <material name="black_plastic">
    <!-- <unreal_material path="Material'/AirSim/VehicleAdv/SUV/AutomotiveMaterials/Materials/Plastic/M_Plastic_Matte.M_Plastic_Matte'"/> -->
    <color rgba="0 1.0 1.0 1.0"/>
  </material>
  <material name="tire_rubber">
    <!-- <unreal_material path="Material'/AirSim/VehicleAdv/SUV/AutomotiveMaterials/Materials/Rubber/M_TireRubber.M_TireRubber'"/> -->
    <color rgba="0 1.0 1.0 1.0"/>
  </material>
  <link name="base_footprint"/>
  <joint name="footprint_mainbox" type="fixed">
    <parent link="base_footprint"/>
    <child link="main_box"/>
    <origin rpy="0 0 0" xyz="0 0 0.3"/>
    <axis rpy="0 0 0" xyz="0 0 1"/>
  </joint>
  <link name="main_box">
    <visual>
      <geometry>
        <box size="1 0.8 0.6"/>
      </geometry>
      <material name="black_plastic"/>
    </visual>
    <collision>
      <geometry>
        <!-- The to-be-commented XML block goes here. -->
        <box size="1 0.8 0.6"/>
      </geometry>
    </collision>
    <inertial>
      <mass value="100"/>
      <inertia ixx="1.0" ixy="0.0" ixz="0.0" iyy="1.0" iyz="0.0" izz="1.0"/>
    </inertial>
  </link>
  <!-- FRONT LEFT LEG -->
  <link name="fl_leg">
    <visual>
      <geometry>
        <box size="0.1 0.1 0.6"/>
      </geometry>
      <material name="black_plastic"/>
    </visual>
    <collision>
      <geometry>
        <box size="0.1 0.1 0.6"/>
      </geometry>
    </collision>
    <inertial>
      <mass value="6"/>
      <inertia ixx="1.0" ixy="0.0" ixz="0.0" iyy="1.0" iyz="0.0" izz="1.0"/>
    </inertial>
  </link>
  <joint name="main_box_to_fl_leg" type="fixed">
    <parent link="main_box"/>
    <child link="fl_leg"/>
    <origin rpy="0 -0.35 0" xyz="0.5 -0.45 -0.5"/>
    <axis rpy="0 0 0" xyz="0 0 1"/>
  </joint>
  <link name="wheel_fl">
    <visual>
      <geometry>
        <cylinder length="0.15" radius="0.2"/>
      </geometry>
      <material name="tire_rubber"/>
    </visual>
    <collision>
      <geometry>
        <cylinder length="0.15" radius="0.2"/>
      </geometry>
    </collision>
    <inertial>
      <mass value="3"/>
      <inertia ixx="1.0" ixy="0.0" ixz="0.0" iyy="1.0" iyz="0.0" izz="1.0"/>
    </inertial>
  </link>
  <joint name="fl_leg_to_wheel_fl" type="continuous">
    <parent link="fl_leg"/>
    <child link="wheel_fl"/>
    <origin rpy="0 1.5707 1.5707" xyz="0.0 -0.13 -0.20"/>
    <axis rpy="0 0 0" xyz="0 0 1"/>
    <!-- <limit lower="0" upper="0" effort="20" velocity="1"/> -->
  </joint>
  <!--============================================================================-->
  <!-- FRONT RIGHT LEG -->
  <link name="fr_leg">
    <visual>
      <geometry>
        <box size="0.1 0.1 0.6"/>
      </geometry>
      <material name="black_plastic"/>
    </visual>
    <collision>
      <geometry>
        <box size="0.1 0.1 0.6"/>
      </geometry>
    </collision>
    <inertial>
      <mass value="6"/>
      <inertia ixx="1.0" ixy="0.0" ixz="0.0" iyy="1.0" iyz="0.0" izz="1.0"/>
    </inertial>
  </link>
  <joint name="main_box_to_fr_leg" type="fixed">
    <parent link="main_box"/>
    <child link="fr_leg"/>
    <origin rpy="0 -0.35 0" xyz="0.5 0.45 -0.5"/>
    <axis rpy="0 0 0" xyz="0 0 1"/>
  </joint>
  <link name="wheel_fr">
    <visual>
      <geometry>
        <cylinder length="0.15" radius="0.2"/>
      </geometry>
      <material name="tire_rubber"/>
    </visual>
    <collision>
      <geometry>
        <cylinder length="0.15" radius="0.2"/>
      </geometry>
    </collision>
    <inertial>
      <mass value="3"/>
      <inertia ixx="1.0" ixy="0.0" ixz="0.0" iyy="1.0" iyz="0.0" izz="1.0"/>
    </inertial>
  </link>
  <joint name="fr_leg_to_wheel_fr" type="continuous">
    <parent link="fr_leg"/>
    <child link="wheel_fr"/>
    <origin rpy="0 1.5707 1.5707" xyz="0.0 0.13 -0.20"/>
    <axis rpy="0 0 0" xyz="0 0 1"/>
    <!-- <limit lower="0" upper="0" effort="20" velocity="1"/> -->
  </joint>
  <!-- BACK STEERING LEFT LEG ===================================================== -->
  <link name="bl_leg">
    <visual>
      <geometry>
        <cylinder length="0.6" radius="0.05"/>
      </geometry>
      <material name="black_plastic"/>
    </visual>
    <collision>
      <geometry>
        <cylinder length="0.6" radius="0.05"/>
      </geometry>
    </collision>
    <inertial>
      <mass value="6"/>
      <inertia ixx="1.0" ixy="0.0" ixz="0.0" iyy="1.0" iyz="0.0" izz="1.0"/>
    </inertial>
  </link>
  <joint name="main_box_to_bl_leg" type="revolute">
    <parent link="main_box"/>
    <child link="bl_leg"/>
    <origin rpy="0 0 0" xyz="-0.5 -0.45 -0.5"/>
    <axis rpy="0 0 0" xyz="0 0 1"/>
    <limit effort="10" lower="-0.5" upper="0.5" velocity="0.5"/>
  </joint>
  <link name="wheel_bl">
    <visual>
      <geometry>
        <cylinder length="0.15" radius="0.2"/>
      </geometry>
      <material name="tire_rubber"/>
    </visual>
    <collision>
      <geometry>
        <cylinder length="0.15" radius="0.2"/>
      </geometry>
    </collision>
    <inertial>
      <mass value="6"/>
      <inertia ixx="1.0" ixy="0.0" ixz="0.0" iyy="1.0" iyz="0.0" izz="1.0"/>
    </inertial>
  </link>
  <joint name="bl_leg_to_wheel_bl" type="continuous">
    <parent link="bl_leg"/>
    <child link="wheel_bl"/>
    <origin rpy="0 1.5707 1.5707" xyz="0.0 -0.13 -0.2"/>
    <axis rpy="0 0 0" xyz="0 0 1"/>
    <limit effort="10000" lower="0" upper="0" velocity="1"/>
  </joint>
  <!-- BACK STEERING RIGHT LEG ====================================================-->
  <link name="br_leg">
    <visual>
      <geometry>
        <cylinder length="0.6" radius="0.05"/>
      </geometry>
      <material name="black_plastic"/>
    </visual>
    <collision>
      <geometry>
        <cylinder length="0.6" radius="0.05"/>
      </geometry>
    </collision>
    <inertial>
      <mass value="6"/>
      <inertia ixx="1.0" ixy="0.0" ixz="0.0" iyy="1.0" iyz="0.0" izz="1.0"/>
    </inertial>
  </link>
  <joint name="main_box_to_br_leg" type="revolute">
    <parent link="main_box"/>
    <child link="br_leg"/>
    <origin rpy="0 0 0" xyz="-0.5 0.45 -0.5"/>
    <axis rpy="0 0 0" xyz="0 0 1"/>
    <limit effort="10" lower="-0.5" upper="0.5" velocity="0.5"/>
  </joint>
  <link name="wheel_br">
    <visual>
      <geometry>
        <cylinder length="0.15" radius="0.2"/>
      </geometry>
      <material name="tire_rubber"/>
    </visual>
    <collision>
      <geometry>
        <cylinder length="0.15" radius="0.2"/>
      </geometry>
    </collision>
    <inertial>
      <mass value="6"/>
      <inertia ixx="1.0" ixy="0.0" ixz="0.0" iyy="1.0" iyz="0.0" izz="1.0"/>
    </inertial>
  </link>
  <joint name="br_leg_to_wheel_br" type="continuous">
    <parent link="br_leg"/>
    <child link="wheel_br"/>
    <origin rpy="0 1.5707 1.5707" xyz="0.0 0.13 -0.2"/>
    <axis rpy="0 0 0" xyz="0 0 1"/>
    <limit effort="10000" lower="0" upper="0" velocity="1"/>
  </joint>
  <link name="realsense_baselink"/>
  <!-- camera body, with origin at bottom screw mount -->
  <joint name="camera_joint" type="fixed">
    <origin rpy="0 0 0" xyz="0 0 0"/>
    <parent link="realsense_baselink"/>
    <child link="camera_bottom_screw_frame"/>
  </joint>
  <link name="camera_bottom_screw_frame"/>
  <joint name="camera_link_joint" type="fixed">
    <origin rpy="0 0 0" xyz="0.010600000000000002 0.0175 0.0125"/>
    <parent link="camera_bottom_screw_frame"/>
    <child link="camera_link"/>
  </joint>
  <link name="camera_link">
    <visual>
      <origin rpy="0 0 0" xyz="0 -0.0175 0"/>
      <geometry>
        <box size="0.02505 0.09 0.025"/>
      </geometry>
      <material name="aluminum"/>
    </visual>
    <collision>
      <origin rpy="0 0 0" xyz="0 -0.0175 0"/>
      <geometry>
        <box size="0.02505 0.09 0.025"/>
      </geometry>
    </collision>
    <inertial>
      <!-- The following are not reliable values, and should not be used for modeling -->
      <mass value="0.072"/>
      <origin xyz="0 0 0"/>
      <inertia ixx="0.003881243" ixy="0.0" ixz="0.0" iyy="0.000498940" iyz="0.0" izz="0.003879257"/>
    </inertial>
  </link>
  <gazebo reference="camera_link">
    <self_collide>0</self_collide>
    <enable_wind>0</enable_wind>
    <kinematic>0</kinematic>
    <gravity>1</gravity>
    <!--<mu>1</mu>-->
    <mu2>1</mu2>
    <fdir1>0 0 0</fdir1>
    <!--<slip1>0</slip1>
      <slip2>0</slip2>-->
    <kp>1e+13</kp>
    <kd>1</kd>
    <!--<max_vel>0.01</max_vel>
      <min_depth>0</min_depth>-->
    <sensor name="cameracolor" type="camera">
      <camera name="camera">
        <horizontal_fov>1.2112585008840648</horizontal_fov>
        <image>
          <width>640</width>
          <height>480</height>
          <format>RGB_INT8</format>
        </image>
        <clip>
          <near>0.1</near>
          <far>100</far>
        </clip>
        <noise>
          <type>gaussian</type>
          <mean>0.0</mean>
          <stddev>0.007</stddev>
        </noise>
      </camera>
      <always_on>1</always_on>
      <update_rate>30</update_rate>
      <visualize>1</visualize>
    </sensor>
    <sensor name="cameraired1" type="camera">
      <camera name="camera">
        <horizontal_fov>1.4870205226991688</horizontal_fov>
        <image>
          <width>1280</width>
          <height>720</height>
          <format>L_INT8</format>
        </image>
        <clip>
          <near>0.1</near>
          <far>100</far>
        </clip>
        <noise>
          <type>gaussian</type>
          <mean>0.0</mean>
          <stddev>0.05</stddev>
        </noise>
      </camera>
      <always_on>1</always_on>
      <update_rate>90</update_rate>
      <visualize>0</visualize>
    </sensor>
    <sensor name="cameraired2" type="camera">
      <camera name="camera">
        <horizontal_fov>1.4870205226991688</horizontal_fov>
        <image>
          <width>1280</width>
          <height>720</height>
          <format>L_INT8</format>
        </image>
        <clip>
          <near>0.1</near>
          <far>100</far>
        </clip>
        <noise>
          <type>gaussian</type>
          <mean>0.0</mean>
          <stddev>0.05</stddev>
        </noise>
      </camera>
      <always_on>1</always_on>
      <update_rate>90</update_rate>
      <visualize>0</visualize>
    </sensor>
    <sensor name="cameradepth" type="depth">
      <camera name="camera">
        <horizontal_fov>1.4870205226991688</horizontal_fov>
        <image>
          <width>1280</width>
          <height>720</height>
        </image>
        <clip>
          <near>0.1</near>
          <far>100</far>
        </clip>
        <noise>
          <type>gaussian</type>
          <mean>0.0</mean>
          <stddev>0.100</stddev>
        </noise>
      </camera>
      <always_on>1</always_on>
      <update_rate>90</update_rate>
      <visualize>0</visualize>
    </sensor>
  </gazebo>
  <gazebo>
    <plugin filename="librealsense_gazebo_plugin.so" name="camera">
      <prefix>camera</prefix>
      <depthUpdateRate>30.0</depthUpdateRate>
      <colorUpdateRate>30.0</colorUpdateRate>
      <infraredUpdateRate>30.0</infraredUpdateRate>
      <depthTopicName>depth/image_raw</depthTopicName>
      <depthCameraInfoTopicName>depth/camera_info</depthCameraInfoTopicName>
      <colorTopicName>color/image_raw</colorTopicName>
      <colorCameraInfoTopicName>color/camera_info</colorCameraInfoTopicName>
      <infrared1TopicName>infra1/image_raw</infrared1TopicName>
      <infrared1CameraInfoTopicName>infra1/camera_info</infrared1CameraInfoTopicName>
      <infrared2TopicName>infra2/image_raw</infrared2TopicName>
      <infrared2CameraInfoTopicName>infra2/camera_info</infrared2CameraInfoTopicName>
      <colorOpticalframeName>camera_color_optical_frame</colorOpticalframeName>
      <depthOpticalframeName>camera_depth_optical_frame</depthOpticalframeName>
      <infrared1OpticalframeName>camera_left_ir_optical_frame</infrared1OpticalframeName>
      <infrared2OpticalframeName>camera_right_ir_optical_frame</infrared2OpticalframeName>
      <rangeMinDepth>0.2</rangeMinDepth>
      <rangeMaxDepth>10.0</rangeMaxDepth>
      <pointCloud>True</pointCloud>
      <pointCloudTopicName>depth/color/points</pointCloudTopicName>
      <pointCloudCutoff>0.25</pointCloudCutoff>
      <pointCloudCutoffMax>9.0</pointCloudCutoffMax>
    </plugin>
  </gazebo>
  <joint name="realsense_bot" type="fixed">
    <parent link="main_box"/>
    <child link="realsense_baselink"/>
    <origin rpy="0 0.5 0" xyz="0.5 0 0.3"/>
    <axis rpy="0 0 0" xyz="0 0 1"/>
  </joint>
</robot>
